2019-11-14 21:09:49.931 [error] <0.359.0>@Elixir.Peex.Events.Repo:init:22 CRASH REPORT Process <0.359.0> with 0 neighbours crashed with reason: bad argument in call to erlang:apply([{username,<<"guest">>},{password,<<"guest">>},{hostname,<<"localhost">>}], username, []) in 'Elixir.Peex.Events.Repo':init/1 line 22
2019-11-15 15:38:18.542 [error] <0.538.0> CRASH REPORT Process <0.538.0> with 0 neighbours exited with reason: {{#{'__exception__' => true,'__struct__' => 'Elixir.ArgumentError',message => <<"argument error">>},[{erlang,apply,[{'Elixir.Peex.Core.StartEvent',#{id => "StartEvent_1",next_node_id => "ScriptTask_0qrmmga"}},id,[]],[]},{'Elixir.Peex.API.Router','-do_match/4-fun-3-',1,[{file,"lib/router.ex"},{line,21}]},{'Elixir.Enum','-map/2-lists^map/1-0-',2,[{file,"lib/enum.ex"},{line,1336}]},{'Elixir.Peex.API.Router','-do_match/4-fun-4-',2,[{file,"lib/router.ex"},{line,21}]},{'Elixir.Peex.API.Router',dispatch,...},...]},...} in 'Elixir.Plug.Cowboy.Handler':exit_on_error/4 line 39 in 'Elixir.Plug.Cowboy.Handler':exit_on_error/4 line 39
2019-11-15 15:38:18.554 [error] <0.298.0> Lager event handler error_logger_lager_h exited with reason {'EXIT',{{case_clause,['Elixir.Peex.API.Router.HTTP',<0.537.0>,1,<0.538.0>,{{#{'__exception__' => true,'__struct__' => 'Elixir.ArgumentError',message => <<"argument error">>},[{erlang,apply,[{'Elixir.Peex.Core.StartEvent',#{id => "StartEvent_1",next_node_id => "ScriptTask_0qrmmga"}},id,[]],[]},{'Elixir.Peex.API.Router','-do_match/4-fun-3-',1,[{file,"lib/router.ex"},{line,21}]},{'Elixir.Enum','-map/2-lists^map/1-0-',2,[{file,"lib/enum.ex"},{line,1336}]},{'Elixir.Peex.API.Router','-do_match/4-fun-4-',...},...]},...},...]},...}}
2019-11-15 16:35:50.957 [error] <0.371.0> gen_server <0.371.0> terminated with reason: {socket_error,timeout}
2019-11-15 16:35:50.957 [error] <0.371.0> CRASH REPORT Process <0.371.0> with 0 neighbours exited with reason: {socket_error,timeout} in gen_server:handle_common_reply/8 line 751
2019-11-15 16:35:50.957 [error] <0.369.0> Supervisor {<0.369.0>,amqp_connection_sup} had child connection started with amqp_gen_connection:start_link(<0.370.0>, {amqp_params_network,<<"guest">>,<<"guest">>,<<"/">>,"localhost",5672,0,0,10,50000,none,[fun amqp_a..>,...],...}) at <0.371.0> exit with reason {socket_error,timeout} in context child_terminated
2019-11-15 16:35:50.957 [error] <0.369.0> Supervisor {<0.369.0>,amqp_connection_sup} had child connection started with amqp_gen_connection:start_link(<0.370.0>, {amqp_params_network,<<"guest">>,<<"guest">>,<<"/">>,"localhost",5672,0,0,10,50000,none,[fun amqp_a..>,...],...}) at <0.371.0> exit with reason reached_max_restart_intensity in context shutdown
