2019-11-18 20:40:52.346 [error] <0.518.0> gen_server {servername,'ServiceTask_1ly7xt9'} terminated with reason: {'module could not be loaded',[{'Elixir.Peex.Example.Service',increment_counter,[#{'__meta__' => #{'__struct__' => 'Elixir.Ecto.Schema.Metadata',context => nil,prefix => nil,schema => 'Elixir.Peex.Contracts.Processtoken',source => <<"processtokens">>,state => loaded},'__struct__' => 'Elixir.Peex.Contracts.Processtoken',correlation_id => <<"2019-11-18 19:40:52.298286Z">>,created_at => #{'__struct__' => 'Elixir.DateTime',calendar => 'Elixir.Calendar.ISO',day => 14,hour => 19,microsecond => {...},...},...}],...},...]}
2019-11-18 20:40:52.346 [error] <0.518.0>@Elixir.Peex.Example.Service:increment_counter CRASH REPORT Process <0.518.0> with 0 neighbours crashed with reason: call to undefined function 'Elixir.Peex.Example.Service':increment_counter(#{'__meta__' => #{'__struct__' => 'Elixir.Ecto.Schema.Metadata',context => nil,prefix => nil,schema => ...,...},...})
2019-11-18 20:40:52.346 [error] <0.514.0>@Elixir.Peex.Example.Service:increment_counter Supervisor 'Elixir.Peex.Core.ProcessSupervisor' had child 'ServiceTask_1ly7xt9' started with 'Elixir.Peex.Core.ServiceTask':start_link(#{id => "ServiceTask_1ly7xt9",instance_id => <<"f2fe8d0f-771c-4b23-8ef5-74fd347008b7">>,name => ...,...}, 'ServiceTask_1ly7xt9') at <0.518.0> exit with reason call to undefined function 'Elixir.Peex.Example.Service':increment_counter(#{'__meta__' => #{'__struct__' => 'Elixir.Ecto.Schema.Metadata',context => nil,prefix => nil,schema => ...,...},...}) in context child_terminated
2019-11-18 21:07:37.979 [error] <0.560.0> CRASH REPORT Process <0.560.0> with 0 neighbours exited with reason: {{#{'__exception__' => true,'__struct__' => 'Elixir.Plug.Conn.AlreadySentError',message => <<"the response was already sent">>},[{'Elixir.Plug.Conn',merge_resp_headers,2,[{file,"lib/plug/conn.ex"},{line,838}]},{'Elixir.CORSPlug',call,2,[{file,"lib/cors_plug.ex"},{line,31}]},{'Elixir.Peex.API.Router',plug_builder_call,2,[{file,"lib/router.ex"},{line,1}]},{'Elixir.Plug.Cowboy.Handler',init,2,[{file,"lib/plug/cowboy/handler.ex"},{line,12}]},{cowboy_handler,execute,2,[{file,"/Users/okti/Dev/St..."},...]},...]},...} in 'Elixir.Plug.Cowboy.Handler':exit_on_error/4 line 39 in 'Elixir.Plug.Cowboy.Handler':exit_on_error/4 line 39
2019-11-18 21:07:37.996 [error] <0.318.0> Lager event handler error_logger_lager_h exited with reason {'EXIT',{{case_clause,['Elixir.Peex.API.Router.HTTP',<0.559.0>,1,<0.560.0>,{{#{'__exception__' => true,'__struct__' => 'Elixir.Plug.Conn.AlreadySentError',message => <<"the response was already sent">>},[{'Elixir.Plug.Conn',merge_resp_headers,2,[{file,"lib/plug/conn.ex"},{line,838}]},{'Elixir.CORSPlug',call,2,[{file,"lib/cors_plug.ex"},{line,31}]},{'Elixir.Peex.API.Router',plug_builder_call,2,[{file,"lib/router.ex"},{line,1}]},{'Elixir.Plug.Cowboy.Handler',init,2,[{file,"lib/plug/cowboy/h..."},...]},...]},...},...]},...}}
2019-11-19 01:24:00.009 [error] <0.368.0> gen_server <0.368.0> terminated with reason: {socket_error,timeout}
2019-11-19 01:24:00.009 [error] <0.368.0> CRASH REPORT Process <0.368.0> with 0 neighbours exited with reason: {socket_error,timeout} in gen_server:handle_common_reply/8 line 751
2019-11-19 01:24:00.009 [error] <0.366.0> Supervisor {<0.366.0>,amqp_connection_sup} had child connection started with amqp_gen_connection:start_link(<0.367.0>, {amqp_params_network,<<"guest">>,<<"guest">>,<<"/">>,"localhost",5672,0,0,10,50000,none,[fun amqp_a..>,...],...}) at <0.368.0> exit with reason {socket_error,timeout} in context child_terminated
